Workbook
Name Slicer_Fuel_Type: #N/A
Name Slicer_Model: #N/A
Name Slicer_Price_Distribution: #N/A
Name Slicer_Region: #N/A
Name Slicer_Year: #N/A

Sheet Pivot
A1: Part 1: Data Exploration & Preparation
A2: 1. Data Overview
A3: Count of Model | B3: Sum of Sales Volume | C3: Average of Base Price (USD) | D3: Sum of Revenue | E3: Average of Horsepower
A4: 54 | B4: 141374 | C4: 374722.22 | D4: 43189580000 | E4: 718.27778
A7: Part 2: Market Structure Analysis
A8: 3. Model Distribution | F8: 4. Regional Sales Analysis | J8: 5. Yearly Sales Trend
A9: Row Labels | B9: Sum of Sales Volume | F9: Row Labels | G9: Sum of Sales Volume | J9: Row Labels | K9: Sum of Sales Volume
A10: Aventador | B10: 5970 | C10: =_xlfn.XLOOKUP(MAX(B10:B15),B10:B15,A10:A15) -> Urus | F10: Americas | G10: 55663 | J10: 2020 | K10: 20250
A11: HuracÃ¡n | B11: 41481 | F11: APAC | G11: 32043 | J11: 2021 | K11: 21925
A12: HuracÃ¡n (Temerario) | B12: 3850 | F12: EMEA | G12: 53668 | J12: 2022 | K12: 24243
A13: Revuelto | B13: 8956 | F13: Grand Total | G13: 141374 | J13: 2023 | K13: 25838
A14: Urus | B14: 54305 | J14: 2024 | K14: 27918
A15: Urus SE | B15: 26812 | J15: 2025 | K15: 21200
A16: Grand Total | B16: 141374 | J16: Grand Total | K16: 141374
A35: Part 3: Pricing & Revenue Analysis
A36: 6. Price Distribution | E36: 7. Price by Model | I36: 8. Revenue Analysis
A37: Row Labels | B37: Sum of Base Price (USD) | E37: Row Labels | F37: Average of Base Price (USD) | I37: Revenue by Model | P37: Revenue by Region
A38: High Price | B38: 8520000 | E38: Aventador | F38: 570000 | I38: Row Labels | J38: Sum of Revenue | P38: Row Labels | Q38: Sum of Revenue
A39: Medium Price | B39: 2685000 | E39: HuracÃ¡n | F39: 278000 | I39: Aventador | J39: 3380955000 | P39: Americas | Q39: 17224970000
A40: Low Price | B40: 9030000 | E40: HuracÃ¡n (Temerario) | F40: 385000 | I40: HuracÃ¡n | J40: 11602560000 | P40: APAC | Q40: 10002955000
A41: Grand Total | B41: 20235000 | E41: Revuelto | F41: 535000 | I41: HuracÃ¡n (Temerario) | J41: 1482750000 | P41: EMEA | Q41: 15961655000
E42: Urus | F42: 243750 | I42: Revuelto | J42: 4827000000 | P42: Grand Total | Q42: 43189580000
E43: Urus SE | F43: 322500 | I43: Urus | J43: 13277465000
E44: Grand Total | F44: 374722.22 | I44: Urus SE | J44: 8618850000
I45: Grand Total | J45: 43189580000
A63: Part 4: Performance Analysis
A64: 9. Horsepower Distribution | E64: 10. Horsepower vs Sales Relationship | I64: 11. Performance vs Price
A65: Row Labels | B65: Sum of Horsepower | E65: Row Labels | F65: Sum of Sales Volume | I65: Row Labels | J65: Average of Base Price (USD)
A66: High HP | B66: 6006 | E66: High HP | F66: 8956 | I66: High HP | J66: 535000
A67: Medium HP | B67: 11778 | E67: Medium HP | F67: 9820 | I67: Medium HP | J67: 533000
A68: Low HP | B68: 21003 | E68: Low HP | F68: 122598 | I68: Low HP | J68: 273636.36
A69: Grand Total | B69: 38787 | E69: Grand Total | F69: 141374 | I69: Grand Total | J69: 374722.22
A87: Part 5: Fuel & Technology Analysis
A88: Year | B88: (All)
A89: 12. Fuel Type Analysis | E89: 13. Fuel Type Pricing Comparison
A90: Row Labels | B90: Sum of Sales Volume | E90: Row Labels | F90: Average of Base Price (USD)
A91: Gasoline | B91: 101756 | E91: Gasoline | F91: 357307.69
A92: Hybrid | B92: 39618 | E92: Hybrid | F92: 420000
A93: Grand Total | B93: 141374 | E93: Grand Total | F93: 374722.22
K114: HP Range | L114: High HP
...

Sheet Work Sheet
A1: Model | B1: Year | C1: Region | D1: Color | E1: Fuel Type | F1: Base Price (USD) | G1: Horsepower | H1: Sales Volume | I1: Turbo (Yes/No) | J1: Price Distribution | K1: Revenue | L1: HP Range
A2: Urus | B2: 2020 | C2: EMEA | D2: Black | E2: Gasoline | F2: 230000 | G2: 641 | H2: 4500 | I2: Yes | J2: {=_xlfn.IFS( F2>520000,"High Price", F2>=350000,"Medium Price", F2<349000,"Low Price")} -> Low Price | K2: =Table1[[#This Row],[Base Price (USD)]]*Table1[[#This Row],[Sales Volume]] -> 1035000000 | L2: {=_xlfn.IFS( G2>=900,"High HP", G2>=750,"Medium HP", G2<750,"Low HP")} -> Low HP
A3: Urus | B3: 2020 | C3: Americas | D3: White | E3: Gasoline | F3: 240000 | G3: 641 | H3: 4800 | I3: Yes | J3: {=_xlfn.IFS( F3>520000,"High Price", F3>=350000,"Medium Price", F3<349000,"Low Price")} -> Low Price | K3: =Table1[[#This Row],[Base Price (USD)]]*Table1[[#This Row],[Sales Volume]] -> 1152000000 | L3: {=_xlfn.IFS( G3>=900,"High HP", G3>=750,"Medium HP", G3<750,"Low HP")} -> Low HP
A4: Urus | B4: 2020 | C4: APAC | D4: Red | E4: Gasoline | F4: 235000 | G4: 641 | H4: 2700 | I4: Yes | J4: {=_xlfn.IFS( F4>520000,"High Price", F4>=350000,"Medium Price", F4<349000,"Low Price")} -> Low Price | K4: =Table1[[#This Row],[Base Price (USD)]]*Table1[[#This Row],[Sales Volume]] -> 634500000 | L4: {=_xlfn.IFS( G4>=900,"High HP", G4>=750,"Medium HP", G4<750,"Low HP")} -> Low HP
A5: HuracÃ¡n | B5: 2020 | C5: EMEA | D5: Yellow | E5: Gasoline | F5: 260000 | G5: 631 | H5: 2500 | I5: Yes | J5: {=_xlfn.IFS( F5>520000,"High Price", F5>=350000,"Medium Price", F5<349000,"Low Price")} -> Low Price | K5: =Table1[[#This Row],[Base Price (USD)]]*Table1[[#This Row],[Sales Volume]] -> 650000000 | L5: {=_xlfn.IFS( G5>=900,"High HP", G5>=750,"Medium HP", G5<750,"Low HP")} -> Low HP
A6: HuracÃ¡n | B6: 2020 | C6: Americas | D6: Orange | E6: Gasoline | F6: 270000 | G6: 631 | H6: 2600 | I6: Yes | J6: {=_xlfn.IFS( F6>520000,"High Price", F6>=350000,"Medium Price", F6<349000,"Low Price")} -> Low Price | K6: =Table1[[#This Row],[Base Price (USD)]]*Table1[[#This Row],[Sales Volume]] -> 702000000 | L6: {=_xlfn.IFS( G6>=900,"High HP", G6>=750,"Medium HP", G6<750,"Low HP")} -> Low HP
A7: HuracÃ¡n | B7: 2020 | C7: APAC | D7: Black | E7: Gasoline | F7: 265000 | G7: 631 | H7: 1500 | I7: Yes | J7: {=_xlfn.IFS( F7>520000,"High Price", F7>=350000,"Medium Price", F7<349000,"Low Price")} -> Low Price | K7: =Table1[[#This Row],[Base Price (USD)]]*Table1[[#This Row],[Sales Volume]] -> 397500000 | L7: {=_xlfn.IFS( G7>=900,"High HP", G7>=750,"Medium HP", G7<750,"Low HP")} -> Low HP
A8: Aventador | B8: 2020 | C8: EMEA | D8: Black | E8: Gasoline | F8: 550000 | G8: 769 | H8: 600 | I8: Yes | J8: {=_xlfn.IFS( F8>520000,"High Price", F8>=350000,"Medium Price", F8<349000,"Low Price")} -> High Price | K8: =Table1[[#This Row],[Base Price (USD)]]*Table1[[#This Row],[Sales Volume]] -> 330000000 | L8: {=_xlfn.IFS( G8>=900,"High HP", G8>=750,"Medium HP", G8<750,"Low HP")} -> Medium HP
A9: Aventador | B9: 2020 | C9: Americas | D9: White | E9: Gasoline | F9: 560000 | G9: 769 | H9: 650 | I9: Yes | J9: {=_xlfn.IFS( F9>520000,"High Price", F9>=350000,"Medium Price", F9<349000,"Low Price")} -> High Price | K9: =Table1[[#This Row],[Base Price (USD)]]*Table1[[#This Row],[Sales Volume]] -> 364000000 | L9: {=_xlfn.IFS( G9>=900,"High HP", G9>=750,"Medium HP", G9<750,"Low HP")} -> Medium HP
A10: Aventador | B10: 2020 | C10: APAC | D10: Red | E10: Gasoline | F10: 555000 | G10: 769 | H10: 400 | I10: Yes | J10: {=_xlfn.IFS( F10>520000,"High Price", F10>=350000,"Medium Price", F10<349000,"Low Price")} -> High Price | K10: =Table1[[#This Row],[Base Price (USD)]]*Table1[[#This Row],[Sales Volume]] -> 222000000 | L10: {=_xlfn.IFS( G10>=900,"High HP", G10>=750,"Medium HP", G10<750,"Low HP")} -> Medium HP
A11: Urus | B11: 2021 | C11: EMEA | D11: Silver | E11: Gasoline | F11: 235000 | G11: 641 | H11: 5021 | I11: Yes | J11: {=_xlfn.IFS( F11>520000,"High Price", F11>=350000,"Medium Price", F11<349000,"Low Price")} -> Low Price | K11: =Table1[[#This Row],[Base Price (USD)]]*Table1[[#This Row],[Sales Volume]] -> 1179935000 | L11: {=_xlfn.IFS( G11>=900,"High HP", G11>=750,"Medium HP", G11<750,"Low HP")} -> Low HP
A12: Urus | B12: 2021 | C12: Americas | D12: Black | E12: Gasoline | F12: 245000 | G12: 641 | H12: 5200 | I12: Yes | J12: {=_xlfn.IFS( F12>520000,"High Price", F12>=350000,"Medium Price", F12<349000,"Low Price")} -> Low Price | K12: =Table1[[#This Row],[Base Price (USD)]]*Table1[[#This Row],[Sales Volume]] -> 1274000000 | L12: {=_xlfn.IFS( G12>=900,"High HP", G12>=750,"Medium HP", G12<750,"Low HP")} -> Low HP
A13: Urus | B13: 2021 | C13: APAC | D13: White | E13: Gasoline | F13: 240000 | G13: 641 | H13: 2780 | I13: Yes | J13: {=_xlfn.IFS( F13>520000,"High Price", F13>=350000,"Medium Price", F13<349000,"Low Price")} -> Low Price | K13: =Table1[[#This Row],[Base Price (USD)]]*Table1[[#This Row],[Sales Volume]] -> 667200000 | L13: {=_xlfn.IFS( G13>=900,"High HP", G13>=750,"Medium HP", G13<750,"Low HP")} -> Low HP
... A55: HuracÃ¡n (Temerario) | B55: 2025 | C55: APAC | D55: White | E55: Hybrid | F55: 385000 | G55: 850 | H55: 1150 | I55: Yes | J55: {=_xlfn.IFS( F55>520000,"High Price", F55>=350000,"Medium Price", F55<349000,"Low Price")} -> Medium Price | K55: =Table1[[#This Row],[Base Price (USD)]]*Table1[[#This Row],[Sales Volume]] -> 442750000 | L55: {=_xlfn.IFS( G55>=900,"High HP", G55>=750,"Medium HP", G55<750,"Low HP")} -> Medium HP

Sheet Assignment
A1: 🚗 Automotive Sales Dashboard – Assignment Questions
A3: Part 1: Data Exploration & Preparation
A4: 1. Data Overview
A5: Create summary KPI cards showing:
A6: Total number of vehicle records
A7: Total sales volume
A8: Average vehicle price
A9: Guiding Question:
A10: What does the overall vehicle market look like in terms of model variety, pricing, and sales activity?
A12: 2. Data Quality Check
A13: Identify and document:
A14: Missing values
... A165: ✅ 2–3 Sentences Insight per Question

Sheet Dashboard
X12: Count of Model | Y12: =GETPIVOTDATA("Model",Pivot!$A$3) -> 54
X13: Sum of Sales Volume | Y13: =GETPIVOTDATA("Sales Volume",Pivot!$B$3) -> 141374
X14: Average of Base Price (USD) | Y14: =GETPIVOTDATA("Base Price (USD)",Pivot!$C$3) -> 374722.22
X15: Sum of Revenue | Y15: =GETPIVOTDATA("Revenue",Pivot!$D$3) -> 43189580000
X16: Average of Horsepower | Y16: =GETPIVOTDATA("Horsepower",Pivot!$E$3) -> 718.27778
X19: Regional Sales Analysis | Y19: =GETPIVOTDATA("Sales Volume",Pivot!$F$9) -> 141374
X25: High HP
X26: Sum of Sales Volume | Y26: =GETPIVOTDATA("Sum of Sales Volume",Pivot!$K$117) -> 8956
X27: Average of Base Price (USD) | Y27: =GETPIVOTDATA("Average of Base Price (USD)",Pivot!$K$117) -> 535000
X30: Best Selling Model | Y30: =Pivot!I148 -> Urus
X31: Highest Revenue Region | Y31: =Pivot!C148 -> Americas
X32: Most Popular Fuel Type | Y32: =Pivot!F148 -> Gasoline
